Workbook

Sheet Parameters
A1: MARTECH 5-YEAR COST MODEL - INDIA PRICING (₹)
A2: ⚠️ Change YELLOW cells to update all calculations
A4: Parameter | B4: Value | C4: Unit | D4: Notes
A5: Number of Contacts/Profiles | B5: 1000000 | C5: contacts | D5: Base contact volume (1M default) - CONFIGURABLE
A6: Contact Growth Rate | B6: 0.15 | C6: % | D6: Annual contact growth (15%)
A7: Tool Subscription Escalation | B7: 0.05 | C7: % | D7: Annual tool cost increase (5%)
A8: Data Storage Growth | B8: 0.15 | C8: % | D8: Annual data growth (15%)

Sheet Tool Costs INR
A1: MARTECH STACK - TOOL-WISE COST (INDIA PRICING ₹)
A2: Based on 1M contacts - India vendor pricing
A4: 1. CDP (Customer Data Platform)
C5: LOW (₹) | D5: MID (₹) | E5: HIGH (₹)
A6: One time implementation cost | C6: =C7 | D6: =D7 | E6: =E7
A7: Ext. resources (Consultant/SI Partner) | C7: 850000 | D7: 2800000 | E7: 4780000
A8: Recurring cost per year | C8: =SUM(C9:C12) | D8: =SUM(D9:D12) | E8: =SUM(E9:E12)
A9: Annual subscription fee | C9: 725000 | D9: 2100000 | E9: 4200000
A10: Recurring data cost | C10: 172800 | D10: 560000 | E10: 1267200
A11: User license fee | C11: 21000 | D11: 63000 | E11: 126000
A12: Maintenance | C12: 30000 | D12: 90000 | E12: 150000
A14: 2. CMP (Campaign Management Platform)
C15: LOW (₹) | D15: MID (₹) | E15: HIGH (₹)
A16: One time implementation cost | C16: =C17 | D16: =D17 | E16: =E17
A17: Ext. resources (Consultant/SI Partner) | C17: 850000 | D17: 2800000 | E17: 4940000
A18: Recurring cost per year | C18: =SUM(C19:C23) | D18: =SUM(D19:D23) | E18: =SUM(E19:E23)
A19: Annual subscription fee | C19: 725000 | D19: 2450000 | E19: 4900000
A20: Recurring data cost | C20: 172800 | D20: 560000 | E20: 1267200
A21: User license fee | C21: 21000 | D21: 63000 | E21: 126000
A22: Maintenance | C22: 30000 | D22: 90000 | E22: 150000
A23: Campaign SMS cost | C23: 0 | D23: 500000 | E23: 1591392
A25: 3. CMS (Content Management System)
C26: LOW (₹) | D26: MID (₹) | E26: HIGH (₹)
A27: One time implementation cost | C27: =C28 | D27: =D28 | E27: =E28
A28: Ext. resources (Consultant/SI Partner) | C28: 450000 | D28: 1500000 | E28: 2864000
A29: Recurring cost per year | C29: =SUM(C30:C33) | D29: =SUM(D30:D33) | E29: =SUM(E30:E33)
A30: Annual subscription fee | C30: 225000 | D30: 1050000 | E30: 2100000
A31: Recurring data cost | C31: 28800 | D31: 280000 | E31: 760320
A32: User license fee | C32: 6000 | D32: 42000 | E32: 84000
A33: Maintenance | C33: 5000 | D33: 35000 | E33: 70000
A35: 4. Experimentation Tool (A/B Testing)
C36: LOW (₹) | D36: MID (₹) | E36: HIGH (₹)
A37: One time implementation cost | C37: =C38 | D37: =D38 | E37: =E38
A38: Ext. resources (Consultant/SI Partner) | C38: 50000 | D38: 500000 | E38: 1660000
A39: Recurring cost per year | C39: =SUM(C40:C43) | D39: =SUM(D40:D43) | E39: =SUM(E40:E43)
A40: Annual subscription fee | C40: 50000 | D40: 525000 | E40: 1050000
A41: Recurring data cost | C41: 28800 | D41: 280000 | E41: 760320
A42: User license fee | C42: 3000 | D42: 21000 | E42: 42000
A43: Maintenance | C43: 5000 | D43: 35000 | E43: 70000
A45: 5. Orchestration Tool (Journey Builder)
...

Sheet Comparison
A1: MARTECH COST COMPARISON - LOW vs MID vs HIGH (₹)
A3: Cost Component | C3: LOW (₹) | D3: MID (₹) | E3: HIGH (₹)
A5: 1. CDP
A6: One time implementation | C6: 850000 | D6: 2800000 | E6: 4780000
A7: Recurring cost per year | C7: 948800 | D7: 2713000 | E7: 5743200
A9: 2. CMP
A10: One time implementation | C10: 850000 | D10: 2800000 | E10: 4940000
A11: Recurring cost per year | C11: 948800 | D11: 3563000 | E11: 7934592
A13: 3. CMS
A14: One time implementation | C14: 450000 | D14: 1500000 | E14: 2864000
A15: Recurring cost per year | C15: 264800 | D15: 1307000 | E15: 2914320
A17: 4. Experimentation
A18: One time implementation | C18: 50000 | D18: 500000 | E18: 1660000
A19: Recurring cost per year | C19: 86800 | D19: 861000 | E19: 1822320
A21: 5. Orchestration
A22: One time implementation | C22: 100000 | D22: 1000000 | E22: 3820000
A23: Recurring cost per year | C23: 186800 | D23: 1811000 | E23: 3922320
A25: 6. Web/App Analytics
A26: One time implementation | C26: 100000 | D26: 1000000 | E26: 3820000
A27: Recurring cost per year | C27: 208000 | D27: 2156000 | E27: 4212000
A29: 7. MMP
A30: One time implementation | C30: 100000 | D30: 500000 | E30: 3320000
A31: Recurring cost per year | C31: 50200 | D31: 721000 | E31: 1422000
A33: 8. Social Management
A34: One time implementation | C34: 50000 | D34: 500000 | E34: 2200000
A35: Recurring cost per year | C35: 86800 | D35: 861000 | E35: 1822320
A37: TOTAL ONE-TIME IMPLEMENTATION | C37: 2550000 | D37: 10600000 | E37: 27404000
A38: TOTAL RECURRING (per year) | C38: 2781000 | D38: 13993000 | E38: 29793072
A39: Ongoing Tech Support (annual) | C39: 0 | D39: 1500000 | E39: 5220000
A41: 5-YEAR TCO CALCULATION
A42: Implementation (Y1 only) | C42: =C37 | D42: =D37 | E42: =E37
A43: Recurring x 5 years | C43: =C38*5 | D43: =D38*5 | E43: =E38*5
A44: Tech Support x 5 years | C44: =C39*5 | D44: =D39*5 | E44: =E39*5
A45: 5-YEAR TCO (₹) | C45: =C42+C43+C44 | D45: =D42+D43+D44 | E45: =E42+E43+E44
A46: 5-YEAR TCO (Lakhs) | C46: =C45/100000 | D46: =D45/100000 | E46: =E45/100000
A47: 5-YEAR TCO (Cr) | C47: =C45/10000000 | D47: =D45/10000000 | E47: =E45/10000000

Sheet Year-by-Year
A1: 5-YEAR DETAILED BREAKDOWN (₹ INR - INDIA PRICING)
A3: Component | B3: Y1 | C3: Y2 | D3: Y3 | E3: Y4 | F3: Y5 | G3: 5-Year Total
A5: LOW MODEL (~₹1 Cr/year)
A6: Implementation | B6: 2600000 | C6: 0 | D6: 0 | E6: 0 | F6: 0 | G6: =SUM(B6:F6)
A7: Recurring | B7: 2781000 | C7: =B7*(1+Parameters!$B$7) | D7: =C7*(1+Parameters!$B$7) | E7: =D7*(1+Parameters!$B$7) | F7: =E7*(1+Parameters!$B$7) | G7: =SUM(B7:F7)
A8: Tech Support | B8: 0 | C8: 0 | D8: 0 | E8: 0 | F8: 0 | G8: =SUM(B8:F8)
A9: TOTAL LOW (₹) | B9: =B6+B7+B8 | C9: =C6+C7+C8 | D9: =D6+D7+D8 | E9: =E6+E7+E8 | F9: =F6+F7+F8 | G9: =G6+G7+G8
A10: TOTAL LOW (Lakhs) | B10: =B9/100000 | C10: =C9/100000 | D10: =D9/100000 | E10: =E9/100000 | F10: =F9/100000 | G10: =G9/100000
A12: MID MODEL (~₹3 Cr/year)
A13: Implementation | B13: 10600000 | C13: 0 | D13: 0 | E13: 0 | F13: 0 | G13: =SUM(B13:F13)
A14: Recurring | B14: 13993000 | C14: =B14*(1+Parameters!$B$7) | D14: =C14*(1+Parameters!$B$7) | E14: =D14*(1+Parameters!$B$7) | F14: =E14*(1+Parameters!$B$7) | G14: =SUM(B14:F14)
A15: Tech Support | B15: 1500000 | C15: =B15*(1+Parameters!$B$7) | D15: =C15*(1+Parameters!$B$7) | E15: =D15*(1+Parameters!$B$7) | F15: =E15*(1+Parameters!$B$7) | G15: =SUM(B15:F15)
A16: TOTAL MID (₹) | B16: =B13+B14+B15 | C16: =C13+C14+C15 | D16: =D13+D14+D15 | E16: =E13+E14+E15 | F16: =F13+F14+F15 | G16: =G13+G14+G15
A17: TOTAL MID (Lakhs) | B17: =B16/100000 | C17: =C16/100000 | D17: =D16/100000 | E17: =E16/100000 | F17: =F16/100000 | G17: =G16/100000
A19: HIGH MODEL (~₹6 Cr/year)
A20: Implementation | B20: 27404000 | C20: 0 | D20: 0 | E20: 0 | F20: 0 | G20: =SUM(B20:F20)
A21: Recurring | B21: 29793072 | C21: =B21*(1+Parameters!$B$7) | D21: =C21*(1+Parameters!$B$7) | E21: =D21*(1+Parameters!$B$7) | F21: =E21*(1+Parameters!$B$7) | G21: =SUM(B21:F21)
A22: Tech Support | B22: 5220000 | C22: =B22*(1+Parameters!$B$7) | D22: =C22*(1+Parameters!$B$7) | E22: =D22*(1+Parameters!$B$7) | F22: =E22*(1+Parameters!$B$7) | G22: =SUM(B22:F22)
A23: TOTAL HIGH (₹) | B23: =B20+B21+B22 | C23: =C20+C21+C22 | D23: =D20+D21+D22 | E23: =E20+E21+E22 | F23: =F20+F21+F22 | G23: =G20+G21+G22
A24: TOTAL HIGH (Lakhs) | B24: =B23/100000 | C24: =C23/100000 | D24: =D23/100000 | E24: =E23/100000 | F24: =F23/100000 | G24: =G23/100000
A25: TOTAL HIGH (Cr) | B25: =B23/10000000 | C25: =C23/10000000 | D25: =D23/10000000 | E25: =E23/10000000 | F25: =F23/10000000 | G25: =G23/10000000

Sheet Summary
A1: MARTECH 5-YEAR COST SUMMARY (₹ INR - INDIA PRICING)
A2: LOW ~₹1 Cr/yr | MID ~₹3 Cr/yr | HIGH ~₹6 Cr/yr
A4: ANNUAL COST SUMMARY
B5: LOW | C5: MID | D5: HIGH
A6: Implementation (One-time) | B6: ₹26 L | C6: ₹1.06 Cr | D6: ₹2.74 Cr
A7: Recurring (Annual) | B7: ₹27.81 L | C7: ₹1.40 Cr | D7: ₹2.98 Cr
A8: Tech Support (Annual) | B8: ₹0 | C8: ₹15 L | D8: ₹52.20 L
A9: TOTAL YEAR 1 | B9: ₹53.81 L | C9: ₹2.61 Cr | D9: ₹6.24 Cr
A12: 5-YEAR TCO SUMMARY
B13: LOW | C13: MID | D13: HIGH
A14: Implementation | B14: ₹26 L | C14: ₹1.06 Cr | D14: ₹2.74 Cr
A15: Recurring (5 years) | B15: ₹1.39 Cr | C15: ₹7.00 Cr | D15: ₹14.90 Cr
A16: Tech Support (5 years) | B16: ₹0 | C16: ₹75 L | D16: ₹2.61 Cr
A17: 5-YEAR TCO | B17: ₹1.65 Cr | C17: ₹8.81 Cr | D17: ₹20.25 Cr
