Workbook

Sheet Parameters
A1: MARTECH 5-YEAR COST MODEL - CONFIGURABLE PARAMETERS
A2: ⚠️ Change YELLOW cells to update all calculations automatically
A4: Parameter | B4: Value | C4: Unit | D4: Notes
A5: Number of Contacts/Profiles | B5: 1000000 | C5: contacts | D5: Base contact volume (1M default)
A6: Contact Growth Rate | B6: 0.15 | C6: % | D6: Annual contact growth (15%)
A7: Tool Subscription Escalation | B7: 0.05 | C7: % | D7: Annual tool cost increase (5%)
A8: Data Storage Growth | B8: 0.15 | C8: % | D8: Annual data growth (15%)
A9: USD to INR Exchange Rate | B9: 83 | C9: INR | D9: Current exchange rate
A10: Implementation Partner Margin | B10: 0.2 | C10: % | D10: SI partner margin on tools

Sheet Tool Costs USD
A1: MARTECH STACK - TOOL-WISE COST BREAKDOWN (USD)
A2: Based on 1M contacts - scales with Parameters sheet
A4: 1. CDP (Customer Data Platform)
C5: LOW ($) | D5: HIGH ($)
A6: One time implementation cost | C6: =C7 | D6: =D7
A7: Ext. resources (Consultant/SI Partner) | C7: 100000 | D7: 250000
A8: Recurring cost per year | C8: =SUM(C9:C12) | D8: =SUM(D9:D12)
A9: Annual subscription fee | C9: 100000 | D9: 200000
A10: Recurring data cost | C10: 28800 | D10: 126720
A11: User license fee | C11: 3000 | D11: 6000
A12: Maintenance | C12: 5000 | D12: 15000
A14: 2. CMP (Campaign Management Platform)
C15: LOW ($) | D15: HIGH ($)
A16: One time implementation cost | C16: =C17 | D16: =D17
A17: Ext. resources (Consultant/SI Partner) | C17: 100000 | D17: 350000
A18: Recurring cost per year | C18: =SUM(C19:C23) | D18: =SUM(D19:D23)
A19: Annual subscription fee | C19: 150000 | D19: 350000
A20: Recurring data cost | C20: 28800 | D20: 126720
A21: User license fee | C21: 3000 | D21: 6000
A22: Maintenance | C22: 5000 | D22: 15000
A23: Campaign SMS cost | C23: 0 | D23: 1591392
A25: 3. CMS (Content Management System)
C26: LOW ($) | D26: HIGH ($)
A27: One time implementation cost | C27: =C28 | D27: =D28
A28: Ext. resources (Consultant/SI Partner) | C28: 450000 | D28: 800000
A29: Recurring cost per year | C29: =SUM(C30:C33) | D29: =SUM(D30:D33)
A30: Annual subscription fee | C30: 225000 | D30: 350000
A31: Recurring data cost | C31: 28800 | D31: 126720
A32: User license fee | C32: 6000 | D32: 12000
A33: Maintenance | C33: 5000 | D33: 15000
A35: 4. Experimentation Tool (A/B Testing)
C36: LOW ($) | D36: HIGH ($)
A37: One time implementation cost | C37: =C38 | D37: =D38
A38: Ext. resources (Consultant/SI Partner) | C38: 50000 | D38: 100000
A39: Recurring cost per year | C39: =SUM(C40:C43) | D39: =SUM(D40:D43)
A40: Annual subscription fee | C40: 50000 | D40: 100000
A41: Recurring data cost | C41: 28800 | D41: 126720
A42: User license fee | C42: 3000 | D42: 6000
A43: Maintenance | C43: 5000 | D43: 15000
A45: 5. Orchestration Tool (Journey Builder)
...

Sheet 5-Year Model
A1: MARTECH 5-YEAR COST MODEL (USD)
A2: All costs in USD - Convert to INR using Parameters!B9
A4: Cost Component | B4: Base (Y1) | C4: Y1 | D4: Y2 | E4: Y3 | F4: Y4 | G4: Y5 | H4: 5-Year Total
A6: SYSTEM TOTALS
A7: One time implementation cost | C7: =C8 | D7: =D8 | E7: =E8 | F7: =F8 | G7: =G8 | H7: =H8
A8: Ext. resources (Consultant/SI Partner) | B8: 850000 | C8: =B8 | D8: 0 | E8: 0 | F8: 0 | G8: 0 | H8: =SUM(C8:G8)
A10: Recurring cost per year | C10: =SUM(C11:C14) | D10: =SUM(D11:D14) | E10: =SUM(E11:E14) | F10: =SUM(F11:F14) | G10: =SUM(G11:G14) | H10: =SUM(H11:H14)
A11: Annual subscription fee (all tools) | B11: 960000 | C11: =B11 | D11: =C11*(1+Parameters!$B$7) | E11: =D11*(1+Parameters!$B$7) | F11: =E11*(1+Parameters!$B$7) | G11: =F11*(1+Parameters!$B$7) | H11: =SUM(C11:G11)
A12: Recurring data cost | B12: 151200 | C12: =B12 | D12: =C12*(1+Parameters!$B$7) | E12: =D12*(1+Parameters!$B$7) | F12: =E12*(1+Parameters!$B$7) | G12: =F12*(1+Parameters!$B$7) | H12: =SUM(C12:G12)
A13: User license fee | B13: 27000 | C13: =B13 | D13: =C13*(1+Parameters!$B$7) | E13: =D13*(1+Parameters!$B$7) | F13: =E13*(1+Parameters!$B$7) | G13: =F13*(1+Parameters!$B$7) | H13: =SUM(C13:G13)
A14: Maintenance | B14: 45000 | C14: =B14 | D14: =C14*(1+Parameters!$B$7) | E14: =D14*(1+Parameters!$B$7) | F14: =E14*(1+Parameters!$B$7) | G14: =F14*(1+Parameters!$B$7) | H14: =SUM(C14:G14)
A17: GRAND TOTAL (USD) | C17: =C7+C10 | D17: =D7+D10 | E17: =E7+E10 | F17: =F7+F10 | G17: =G7+G10 | H17: =H7+H10
A18: GRAND TOTAL (INR Lakhs) | C18: =(C17*Parameters!$B$9)/100000 | D18: =(D17*Parameters!$B$9)/100000 | E18: =(E17*Parameters!$B$9)/100000 | F18: =(F17*Parameters!$B$9)/100000 | G18: =(G17*Parameters!$B$9)/100000 | H18: =(H17*Parameters!$B$9)/100000
A19: GRAND TOTAL (INR Cr) | C19: =(C17*Parameters!$B$9)/10000000 | D19: =(D17*Parameters!$B$9)/10000000 | E19: =(E17*Parameters!$B$9)/10000000 | F19: =(F17*Parameters!$B$9)/10000000 | G19: =(G17*Parameters!$B$9)/10000000 | H19: =(H17*Parameters!$B$9)/10000000

Sheet Low vs High
A1: MARTECH COST COMPARISON - LOW vs HIGH (USD)
A3: Cost Component | C3: LOW | D3: HIGH
A5: 1. CDP
A6: One time implementation | C6: 100000 | D6: 250000
A7: Recurring cost per year | C7: 136800 | D7: 347720
A9: 2. CMP
A10: One time implementation | C10: 100000 | D10: 350000
A11: Recurring cost per year | C11: 186800 | D11: 497720
A13: 3. CMS
A14: One time implementation | C14: 450000 | D14: 800000
A15: Recurring cost per year | C15: 264800 | D15: 503720
A17: 4. Experimentation Tool
A18: One time implementation | C18: 50000 | D18: 100000
A19: Recurring cost per year | C19: 86800 | D19: 247720
A21: 5. Orchestration Tool
A22: One time implementation | C22: 100000 | D22: 250000
A23: Recurring cost per year | C23: 186800 | D23: 447720
A25: 6. Web/App Analytics
A26: One time implementation | C26: 100000 | D26: 250000
A27: Recurring cost per year | C27: 208000 | D27: 421000
A29: 7. MMP
A30: One time implementation | C30: 100000 | D30: 200000
A31: Recurring cost per year | C31: 50200 | D31: 157000
A33: 8. Social Management Tool
A34: One time implementation | C34: 50000 | D34: 150000
A35: Recurring cost per year | C35: 86800 | D35: 297720
A37: TOTAL ONE-TIME IMPLEMENTATION | C37: =1050000 | D37: =2350000
A38: TOTAL RECURRING (per year) | C38: =1207000 | D38: =2920320
A39: Ongoing Tech Support (annual) | C39: 0 | D39: 522000
A41: 5-YEAR TCO CALCULATION
A42: Implementation (Y1 only) | C42: 1050000 | D42: 2350000
A43: Recurring x 5 years | C43: =1207000*5 | D43: =2920320*5
A44: Tech Support x 5 years | C44: 0 | D44: =522000*5
A45: 5-YEAR TCO (USD) | C45: =C42+C43+C44 | D45: =D42+D43+D44
A46: 5-YEAR TCO (INR Lakhs) | C46: =(C45*Parameters!$B$9)/100000 | D46: =(D45*Parameters!$B$9)/100000
A47: 5-YEAR TCO (INR Cr) | C47: =(C45*Parameters!$B$9)/10000000 | D47: =(D45*Parameters!$B$9)/10000000

Sheet Year-by-Year
A1: 5-YEAR DETAILED BREAKDOWN (USD)
A3: Component | B3: Y1 | C3: Y2 | D3: Y3 | E3: Y4 | F3: Y5 | G3: 5-Year Total
A5: LOW MODEL
A6: Implementation | B6: 1050000 | C6: 0 | D6: 0 | E6: 0 | F6: 0 | G6: =SUM(B6:F6)
A7: Recurring (base) | B7: 1207000 | C7: =B7*(1+Parameters!$B$7) | D7: =C7*(1+Parameters!$B$7) | E7: =D7*(1+Parameters!$B$7) | F7: =E7*(1+Parameters!$B$7) | G7: =SUM(B7:F7)
A8: TOTAL LOW (USD) | B8: =B6+B7 | C8: =C6+C7 | D8: =D6+D7 | E8: =E6+E7 | F8: =F6+F7 | G8: =G6+G7
A9: TOTAL LOW (INR Lakhs) | B9: =(B8*Parameters!$B$9)/100000 | C9: =(C8*Parameters!$B$9)/100000 | D9: =(D8*Parameters!$B$9)/100000 | E9: =(E8*Parameters!$B$9)/100000 | F9: =(F8*Parameters!$B$9)/100000 | G9: =(G8*Parameters!$B$9)/100000
A11: HIGH MODEL
A12: Implementation | B12: 2350000 | C12: 0 | D12: 0 | E12: 0 | F12: 0 | G12: =SUM(B12:F12)
A13: Recurring (base) | B13: 2920320 | C13: =B13*(1+Parameters!$B$7) | D13: =C13*(1+Parameters!$B$7) | E13: =D13*(1+Parameters!$B$7) | F13: =E13*(1+Parameters!$B$7) | G13: =SUM(B13:F13)
A14: Tech Support | B14: 522000 | C14: =B14*(1+Parameters!$B$7) | D14: =C14*(1+Parameters!$B$7) | E14: =D14*(1+Parameters!$B$7) | F14: =E14*(1+Parameters!$B$7) | G14: =SUM(B14:F14)
A15: TOTAL HIGH (USD) | B15: =B12+B13+B14 | C15: =C12+C13+C14 | D15: =D12+D13+D14 | E15: =E12+E13+E14 | F15: =F12+F13+F14 | G15: =G12+G13+G14
A16: TOTAL HIGH (INR Lakhs) | B16: =(B15*Parameters!$B$9)/100000 | C16: =(C15*Parameters!$B$9)/100000 | D16: =(D15*Parameters!$B$9)/100000 | E16: =(E15*Parameters!$B$9)/100000 | F16: =(F15*Parameters!$B$9)/100000 | G16: =(G15*Parameters!$B$9)/100000
A17: TOTAL HIGH (INR Cr) | B17: =(B15*Parameters!$B$9)/10000000 | C17: =(C15*Parameters!$B$9)/10000000 | D17: =(D15*Parameters!$B$9)/10000000 | E17: =(E15*Parameters!$B$9)/10000000 | F17: =(F15*Parameters!$B$9)/10000000 | G17: =(G15*Parameters!$B$9)/10000000
