Workbook

Sheet Parameters
A1: MARTECH 5-YEAR COST MODEL - INPUT PARAMETERS
A2: ⚠️ Change YELLOW cells to update all calculations automatically
A4: Parameter | B4: Value | C4: Unit | D4: Notes
A5: Tool Subscription Escalation | B5: 0.05 | C5: % | D5: Annual increase in tool costs (5%)
A6: Data Storage Growth | B6: 0.15 | C6: % | D6: Annual increase due to data volume (15%)
A7: MMP Cost Growth | B7: 0.15 | C7: % | D7: Usage-based annual increase (15%)
A8: Team Salary Increment | B8: 0.1 | C8: % | D8: Annual salary hike (10%)
A9: Maintenance Escalation | B9: 0.05 | C9: % | D9: Annual maintenance cost increase (5%)

Sheet LOW Model
A1: LOW COST MODEL - 5 YEAR PROJECTION
A3: IMPLEMENTATION COSTS (ONE-TIME)
A4: Cost Component | B4: Amount (₹) | H4: Notes
A5: Int. resources | B5: 250000 | H5: Internal team setup
A6: Ext. resources (SI Partner) | B6: 1000000 | H6: Consultant/Implementation
A7: IMPLEMENTATION TOTAL | B7: =B5+B6
A9: TOOL COSTS (RECURRING)
A10: Cost Component | B10: Base (Y1) | C10: Y1 | D10: Y2 | E10: Y3 | F10: Y4 | G10: Y5 | H10: 5-Year Total
A11: CDP + CMP Subscription | B11: 350000 | C11: =B11 | D11: =C11*(1+Parameters!$B$5) | E11: =D11*(1+Parameters!$B$5) | F11: =E11*(1+Parameters!$B$5) | G11: =F11*(1+Parameters!$B$5) | H11: =SUM(C11:G11)
A12: Data Lake / Storage | B12: 60000 | C12: =B12 | D12: =C12*(1+Parameters!$B$6) | E12: =D12*(1+Parameters!$B$6) | F12: =E12*(1+Parameters!$B$6) | G12: =F12*(1+Parameters!$B$6) | H12: =SUM(C12:G12)
A13: Analytics + BI License | B13: 100000 | C13: =B13 | D13: =C13*(1+Parameters!$B$5) | E13: =D13*(1+Parameters!$B$5) | F13: =E13*(1+Parameters!$B$5) | G13: =F13*(1+Parameters!$B$5) | H13: =SUM(C13:G13)
A14: CMS Hosting | B14: 30000 | C14: =B14 | D14: =C14*(1+Parameters!$B$5) | E14: =D14*(1+Parameters!$B$5) | F14: =E14*(1+Parameters!$B$5) | G14: =F14*(1+Parameters!$B$5) | H14: =SUM(C14:G14)
A15: MMP (Free tier) | B15: 30000 | C15: =B15 | D15: =B15 | E15: =B15 | F15: =B15 | G15: =B15 | H15: =SUM(C15:G15)
A16: Maintenance & Support | B16: 50000 | C16: =B16 | D16: =C16*(1+Parameters!$B$9) | E16: =D16*(1+Parameters!$B$9) | F16: =E16*(1+Parameters!$B$9) | G16: =F16*(1+Parameters!$B$9) | H16: =SUM(C16:G16)
A17: TOOLS TOTAL | C17: =SUM(C11:C16) | D17: =SUM(D11:D16) | E17: =SUM(E11:E16) | F17: =SUM(F11:F16) | G17: =SUM(G11:G16) | H17: =SUM(H11:H16)
A19: TEAM COSTS
A20: Role | B20: Base CTC (Y1) | C20: Y1 | D20: Y2 | E20: Y3 | F20: Y4 | G20: Y5 | H20: 5-Year Total
A21: Martech Lead (1) | B21: 1800000 | C21: =B21 | D21: =C21*(1+Parameters!$B$8) | E21: =D21*(1+Parameters!$B$8) | F21: =E21*(1+Parameters!$B$8) | G21: =F21*(1+Parameters!$B$8) | H21: =SUM(C21:G21)
A22: Automation Specialist (1) | B22: 800000 | C22: =B22 | D22: =C22*(1+Parameters!$B$8) | E22: =D22*(1+Parameters!$B$8) | F22: =E22*(1+Parameters!$B$8) | G22: =F22*(1+Parameters!$B$8) | H22: =SUM(C22:G22)
A23: Junior Analyst (1) | B23: 500000 | C23: =B23 | D23: =C23*(1+Parameters!$B$8) | E23: =D23*(1+Parameters!$B$8) | F23: =E23*(1+Parameters!$B$8) | G23: =F23*(1+Parameters!$B$8) | H23: =SUM(C23:G23)
A24: TEAM TOTAL (3 members) | C24: =SUM(C21:C23) | D24: =SUM(D21:D23) | E24: =SUM(E21:E23) | F24: =SUM(F21:F23) | G24: =SUM(G21:G23) | H24: =SUM(H21:H23)
A26: YEAR TOTALS
A27: Component | B27: Y1 | C27: Y2 | D27: Y3 | E27: Y4 | F27: Y5 | G27: 5-Year Total
A28: Implementation | B28: =B7 | C28: 0 | D28: 0 | E28: 0 | F28: 0 | G28: =SUM(B28:F28)
A29: Tools | B29: =C17 | C29: =D17 | D29: =E17 | E29: =F17 | F29: =G17 | G29: =H17
A30: Team | B30: =C24 | C30: =D24 | D30: =E24 | E30: =F24 | F30: =G24 | G30: =H24
A31: YEAR TOTAL (₹) | B31: =SUM(B28:B30) | C31: =SUM(C28:C30) | D31: =SUM(D28:D30) | E31: =SUM(E28:E30) | F31: =SUM(F28:F30) | G31: =SUM(G28:G30)
A32: YEAR TOTAL (Lakhs) | B32: =B31/100000 | C32: =C31/100000 | D32: =D31/100000 | E32: =E31/100000 | F32: =F31/100000 | G32: =G31/100000

Sheet MID Model
A1: MID COST MODEL - 5 YEAR PROJECTION
A3: IMPLEMENTATION COSTS (ONE-TIME)
A4: Cost Component | B4: Amount (₹) | H4: Notes
A5: Int. resources | B5: 500000 | H5: Internal team setup
A6: Ext. resources (SI Partner) | B6: 2300000 | H6: Consultant/Implementation
A7: IMPLEMENTATION TOTAL | B7: =B5+B6
A9: TOOL COSTS (RECURRING)
A10: Cost Component | B10: Base (Y1) | C10: Y1 | D10: Y2 | E10: Y3 | F10: Y4 | G10: Y5 | H10: 5-Year Total
A11: CDP + CMP Subscription | B11: 900000 | C11: =B11 | D11: =C11*(1+Parameters!$B$5) | E11: =D11*(1+Parameters!$B$5) | F11: =E11*(1+Parameters!$B$5) | G11: =F11*(1+Parameters!$B$5) | H11: =SUM(C11:G11)
A12: Data Lake / Storage | B12: 120000 | C12: =B12 | D12: =C12*(1+Parameters!$B$6) | E12: =D12*(1+Parameters!$B$6) | F12: =E12*(1+Parameters!$B$6) | G12: =F12*(1+Parameters!$B$6) | H12: =SUM(C12:G12)
A13: Analytics + BI License | B13: 180000 | C13: =B13 | D13: =C13*(1+Parameters!$B$5) | E13: =D13*(1+Parameters!$B$5) | F13: =E13*(1+Parameters!$B$5) | G13: =F13*(1+Parameters!$B$5) | H13: =SUM(C13:G13)
A14: CMS Hosting | B14: 75000 | C14: =B14 | D14: =C14*(1+Parameters!$B$5) | E14: =D14*(1+Parameters!$B$5) | F14: =E14*(1+Parameters!$B$5) | G14: =F14*(1+Parameters!$B$5) | H14: =SUM(C14:G14)
A15: MMP (Usage-based) | B15: 170000 | C15: =B15 | D15: =C15*(1+Parameters!$B$7) | E15: =D15*(1+Parameters!$B$7) | F15: =E15*(1+Parameters!$B$7) | G15: =F15*(1+Parameters!$B$7) | H15: =SUM(C15:G15)
A16: Maintenance & Support | B16: 100000 | C16: =B16 | D16: =C16*(1+Parameters!$B$9) | E16: =D16*(1+Parameters!$B$9) | F16: =E16*(1+Parameters!$B$9) | G16: =F16*(1+Parameters!$B$9) | H16: =SUM(C16:G16)
A17: TOOLS TOTAL | C17: =SUM(C11:C16) | D17: =SUM(D11:D16) | E17: =SUM(E11:E16) | F17: =SUM(F11:F16) | G17: =SUM(G11:G16) | H17: =SUM(H11:H16)
A19: TEAM COSTS (Head of Martech is OPTIONAL)
A20: Role | B20: Base CTC (Y1) | C20: Y1 | D20: Y2 | E20: Y3 | F20: Y4 | G20: Y5 | H20: 5-Year Total
A21: Head of Martech (OPTIONAL) | B21: 2500000 | C21: =B21 | D21: =C21*(1+Parameters!$B$8) | E21: =D21*(1+Parameters!$B$8) | F21: =E21*(1+Parameters!$B$8) | G21: =F21*(1+Parameters!$B$8) | H21: =SUM(C21:G21)
A22: Automation Lead (1) | B22: 1400000 | C22: =B22 | D22: =C22*(1+Parameters!$B$8) | E22: =D22*(1+Parameters!$B$8) | F22: =E22*(1+Parameters!$B$8) | G22: =F22*(1+Parameters!$B$8) | H22: =SUM(C22:G22)
A23: CDP/Data Analyst (1) | B23: 1000000 | C23: =B23 | D23: =C23*(1+Parameters!$B$8) | E23: =D23*(1+Parameters!$B$8) | F23: =E23*(1+Parameters!$B$8) | G23: =F23*(1+Parameters!$B$8) | H23: =SUM(C23:G23)
A24: Content Specialist (1) | B24: 600000 | C24: =B24 | D24: =C24*(1+Parameters!$B$8) | E24: =D24*(1+Parameters!$B$8) | F24: =E24*(1+Parameters!$B$8) | G24: =F24*(1+Parameters!$B$8) | H24: =SUM(C24:G24)
A25: Junior Executive (1) | B25: 400000 | C25: =B25 | D25: =C25*(1+Parameters!$B$8) | E25: =D25*(1+Parameters!$B$8) | F25: =E25*(1+Parameters!$B$8) | G25: =F25*(1+Parameters!$B$8) | H25: =SUM(C25:G25)
A26: TEAM TOTAL (5 with Head) | C26: =SUM(C21:C25) | D26: =SUM(D21:D25) | E26: =SUM(E21:E25) | F26: =SUM(F21:F25) | G26: =SUM(G21:G25) | H26: =SUM(H21:H25)
A27: TEAM TOTAL (4 without Head) | C27: =SUM(C22:C25) | D27: =SUM(D22:D25) | E27: =SUM(E22:E25) | F27: =SUM(F22:F25) | G27: =SUM(G22:G25) | H27: =SUM(H22:H25)
A29: YEAR TOTALS (WITH HEAD)
A30: Component | B30: Y1 | C30: Y2 | D30: Y3 | E30: Y4 | F30: Y5 | G30: 5-Year Total
A31: Implementation | B31: =B7 | C31: 0 | D31: 0 | E31: 0 | F31: 0 | G31: =SUM(B31:F31)
A32: Tools | B32: =C17 | C32: =D17 | D32: =E17 | E32: =F17 | F32: =G17 | G32: =H17
A33: Team (with Head) | B33: =C26 | C33: =D26 | D33: =E26 | E33: =F26 | F33: =G26 | G33: =H26
A34: TOTAL WITH HEAD (₹) | B34: =SUM(B31:B33) | C34: =SUM(C31:C33) | D34: =SUM(D31:D33) | E34: =SUM(E31:E33) | F34: =SUM(F31:F33) | G34: =SUM(G31:G33)
A35: TOTAL WITH HEAD (Lakhs) | B35: =B34/100000 | C35: =C34/100000 | D35: =D34/100000 | E35: =E34/100000 | F35: =F34/100000 | G35: =G34/100000
A37: YEAR TOTALS (WITHOUT HEAD)
A38: Component | B38: Y1 | C38: Y2 | D38: Y3 | E38: Y4 | F38: Y5 | G38: 5-Year Total
A39: Implementation | B39: =B7 | C39: 0 | D39: 0 | E39: 0 | F39: 0 | G39: =SUM(B39:F39)
A40: Tools | B40: =C17 | C40: =D17 | D40: =E17 | E40: =F17 | F40: =G17 | G40: =H17
A41: Team (without Head) | B41: =C27 | C41: =D27 | D41: =E27 | E41: =F27 | F41: =G27 | G41: =H27
A42: TOTAL WITHOUT HEAD (₹) | B42: =SUM(B39:B41) | C42: =SUM(C39:C41) | D42: =SUM(D39:D41) | E42: =SUM(E39:E41) | F42: =SUM(F39:F41) | G42: =SUM(G39:G41)
A43: TOTAL WITHOUT HEAD (Lakhs) | B43: =B42/100000 | C43: =C42/100000 | D43: =D42/100000 | E43: =E42/100000 | F43: =F42/100000 | G43: =G42/100000

Sheet HIGH Model
A1: HIGH COST MODEL - 5 YEAR PROJECTION
A3: IMPLEMENTATION COSTS (ONE-TIME)
A4: Cost Component | B4: Amount (₹) | H4: Notes
A5: Int. resources | B5: 1000000 | H5: Internal team setup
A6: Ext. resources (SI Partner) | B6: 4500000 | H6: Consultant/Implementation
A7: IMPLEMENTATION TOTAL | B7: =B5+B6
A9: TOOL COSTS (RECURRING)
A10: Cost Component | B10: Base (Y1) | C10: Y1 | D10: Y2 | E10: Y3 | F10: Y4 | G10: Y5 | H10: 5-Year Total
A11: CDP Subscription | B11: 1800000 | C11: =B11 | D11: =C11*(1+Parameters!$B$5) | E11: =D11*(1+Parameters!$B$5) | F11: =E11*(1+Parameters!$B$5) | G11: =F11*(1+Parameters!$B$5) | H11: =SUM(C11:G11)
A12: CMP Subscription | B12: 600000 | C12: =B12 | D12: =C12*(1+Parameters!$B$5) | E12: =D12*(1+Parameters!$B$5) | F12: =E12*(1+Parameters!$B$5) | G12: =F12*(1+Parameters!$B$5) | H12: =SUM(C12:G12)
A13: Data Lake / Storage | B13: 300000 | C13: =B13 | D13: =C13*(1+Parameters!$B$6) | E13: =D13*(1+Parameters!$B$6) | F13: =E13*(1+Parameters!$B$6) | G13: =F13*(1+Parameters!$B$6) | H13: =SUM(C13:G13)
A14: Analytics Workbench | B14: 400000 | C14: =B14 | D14: =C14*(1+Parameters!$B$5) | E14: =D14*(1+Parameters!$B$5) | F14: =E14*(1+Parameters!$B$5) | G14: =F14*(1+Parameters!$B$5) | H14: =SUM(C14:G14)
A15: Personalization Engine | B15: 300000 | C15: =B15 | D15: =C15*(1+Parameters!$B$5) | E15: =D15*(1+Parameters!$B$5) | F15: =E15*(1+Parameters!$B$5) | G15: =F15*(1+Parameters!$B$5) | H15: =SUM(C15:G15)
A16: CMS (Enterprise) | B16: 400000 | C16: =B16 | D16: =C16*(1+Parameters!$B$5) | E16: =D16*(1+Parameters!$B$5) | F16: =E16*(1+Parameters!$B$5) | G16: =F16*(1+Parameters!$B$5) | H16: =SUM(C16:G16)
A17: MMP (Enterprise) | B17: 400000 | C17: =B17 | D17: =C17*(1+Parameters!$B$7) | E17: =D17*(1+Parameters!$B$7) | F17: =E17*(1+Parameters!$B$7) | G17: =F17*(1+Parameters!$B$7) | H17: =SUM(C17:G17)
A18: BI License (10 users) | B18: 240000 | C18: =B18 | D18: =C18*(1+Parameters!$B$5) | E18: =D18*(1+Parameters!$B$5) | F18: =E18*(1+Parameters!$B$5) | G18: =F18*(1+Parameters!$B$5) | H18: =SUM(C18:G18)
A19: Maintenance & Support | B19: 200000 | C19: =B19 | D19: =C19*(1+Parameters!$B$9) | E19: =D19*(1+Parameters!$B$9) | F19: =E19*(1+Parameters!$B$9) | G19: =F19*(1+Parameters!$B$9) | H19: =SUM(C19:G19)
A20: TOOLS TOTAL | C20: =SUM(C11:C19) | D20: =SUM(D11:D19) | E20: =SUM(E11:E19) | F20: =SUM(F11:F19) | G20: =SUM(G11:G19) | H20: =SUM(H11:H19)
A22: TEAM COSTS (Head of Martech is OPTIONAL)
A23: Role | B23: Base CTC (Y1) | C23: Y1 | D23: Y2 | E23: Y3 | F23: Y4 | G23: Y5 | H23: 5-Year Total
A24: Head of Martech (OPTIONAL) | B24: 3200000 | C24: =B24 | D24: =C24*(1+Parameters!$B$8) | E24: =D24*(1+Parameters!$B$8) | F24: =E24*(1+Parameters!$B$8) | G24: =F24*(1+Parameters!$B$8) | H24: =SUM(C24:G24)
A25: Automation Lead (1) | B25: 1600000 | C25: =B25 | D25: =C25*(1+Parameters!$B$8) | E25: =D25*(1+Parameters!$B$8) | F25: =E25*(1+Parameters!$B$8) | G25: =F25*(1+Parameters!$B$8) | H25: =SUM(C25:G25)
A26: Sr. CDP Analyst (1) | B26: 1400000 | C26: =B26 | D26: =C26*(1+Parameters!$B$8) | E26: =D26*(1+Parameters!$B$8) | F26: =E26*(1+Parameters!$B$8) | G26: =F26*(1+Parameters!$B$8) | H26: =SUM(C26:G26)
A27: Jr. Data Analyst (1) | B27: 700000 | C27: =B27 | D27: =C27*(1+Parameters!$B$8) | E27: =D27*(1+Parameters!$B$8) | F27: =E27*(1+Parameters!$B$8) | G27: =F27*(1+Parameters!$B$8) | H27: =SUM(C27:G27)
A28: Content Specialist (1) | B28: 800000 | C28: =B28 | D28: =C28*(1+Parameters!$B$8) | E28: =D28*(1+Parameters!$B$8) | F28: =E28*(1+Parameters!$B$8) | G28: =F28*(1+Parameters!$B$8) | H28: =SUM(C28:G28)
A29: Executive (1) | B29: 500000 | C29: =B29 | D29: =C29*(1+Parameters!$B$8) | E29: =D29*(1+Parameters!$B$8) | F29: =E29*(1+Parameters!$B$8) | G29: =F29*(1+Parameters!$B$8) | H29: =SUM(C29:G29)
A30: TEAM TOTAL (6 with Head) | C30: =SUM(C24:C29) | D30: =SUM(D24:D29) | E30: =SUM(E24:E29) | F30: =SUM(F24:F29) | G30: =SUM(G24:G29) | H30: =SUM(H24:H29)
A31: TEAM TOTAL (5 without Head) | C31: =SUM(C25:C29) | D31: =SUM(D25:D29) | E31: =SUM(E25:E29) | F31: =SUM(F25:F29) | G31: =SUM(G25:G29) | H31: =SUM(H25:H29)
A33: YEAR TOTALS (WITH HEAD)
A34: Component | B34: Y1 | C34: Y2 | D34: Y3 | E34: Y4 | F34: Y5 | G34: 5-Year Total
A35: Implementation | B35: =B7 | C35: 0 | D35: 0 | E35: 0 | F35: 0 | G35: =SUM(B35:F35)
A36: Tools | B36: =C20 | C36: =D20 | D36: =E20 | E36: =F20 | F36: =G20 | G36: =H20
A37: Team (with Head) | B37: =C30 | C37: =D30 | D37: =E30 | E37: =F30 | F37: =G30 | G37: =H30
A38: TOTAL WITH HEAD (₹) | B38: =SUM(B35:B37) | C38: =SUM(C35:C37) | D38: =SUM(D35:D37) | E38: =SUM(E35:E37) | F38: =SUM(F35:F37) | G38: =SUM(G35:G37)
A39: TOTAL WITH HEAD (Lakhs) | B39: =B38/100000 | C39: =C38/100000 | D39: =D38/100000 | E39: =E38/100000 | F39: =F38/100000 | G39: =G38/100000
A41: YEAR TOTALS (WITHOUT HEAD)
A42: Component | B42: Y1 | C42: Y2 | D42: Y3 | E42: Y4 | F42: Y5 | G42: 5-Year Total
A43: Implementation | B43: =B7 | C43: 0 | D43: 0 | E43: 0 | F43: 0 | G43: =SUM(B43:F43)
A44: Tools | B44: =C20 | C44: =D20 | D44: =E20 | E44: =F20 | F44: =G20 | G44: =H20
A45: Team (without Head) | B45: =C31 | C45: =D31 | D45: =E31 | E45: =F31 | F45: =G31 | G45: =H31
...

Sheet Summary
A1: MARTECH COST MODEL - SUMMARY COMPARISON
A3: 5-YEAR TCO COMPARISON (ALL MODELS)
A4: Model | B4: Y1 | C4: Y2 | D4: Y3 | E4: Y4 | F4: Y5 | G4: 5-Year TCO | H4: TCO (Cr)
A5: LOW (3 team) | B5: ='LOW Model'!B31 | C5: ='LOW Model'!C31 | D5: ='LOW Model'!D31 | E5: ='LOW Model'!E31 | F5: ='LOW Model'!F31 | G5: ='LOW Model'!G31 | H5: =G5/10000000
A6: MID with Head (5 team) | B6: ='MID Model'!B34 | C6: ='MID Model'!C34 | D6: ='MID Model'!D34 | E6: ='MID Model'!E34 | F6: ='MID Model'!F34 | G6: ='MID Model'!G34 | H6: =G6/10000000
A7: MID without Head (4 team) | B7: ='MID Model'!B42 | C7: ='MID Model'!C42 | D7: ='MID Model'!D42 | E7: ='MID Model'!E42 | F7: ='MID Model'!F42 | G7: ='MID Model'!G42 | H7: =G7/10000000
A8: HIGH with Head (6 team) | B8: ='HIGH Model'!B38 | C8: ='HIGH Model'!C38 | D8: ='HIGH Model'!D38 | E8: ='HIGH Model'!E38 | F8: ='HIGH Model'!F38 | G8: ='HIGH Model'!G38 | H8: =G8/10000000
A9: HIGH without Head (5 team) | B9: ='HIGH Model'!B46 | C9: ='HIGH Model'!C46 | D9: ='HIGH Model'!D46 | E9: ='HIGH Model'!E46 | F9: ='HIGH Model'!F46 | G9: ='HIGH Model'!G46 | H9: =G9/10000000
A12: SAVINGS BY REMOVING HEAD OF MARTECH
A13: Model | B13: 5-Year Savings (₹) | C13: Savings (Lakhs)
A14: MID Model | B14: =G6-G7 | C14: =B14/100000
A15: HIGH Model | B15: =G8-G9 | C15: =B15/100000
