Workbook

Sheet A_Assumptions
A1: ICICI LOMBARD D2C MODEL - MASTER ASSUMPTIONS
A3: ID | B3: Parameter | C3: Value | D3: Unit | E3: Source | F3: Citation
A4: MARKET SIZE
A5: M1 | B5: Total Health Insurance GWP FY24 | C5: 117000 | D5: ₹ Crore | E5: IRDAI AR 2023-24 | F5: Page 45, Table 3.1
A6: M2 | B6: Retail Health % of Total | C6: 0.387 | D6: % | E6: Niva Bupa DRHP | F6: Page 15, Industry Report
A7: M3 | B7: Group Health % of Total | C7: 0.505 | D7: % | E7: Niva Bupa DRHP | F7: Page 15, Industry Report
A8: M4 | B8: Govt Schemes % of Total | C8: 0.097 | D8: % | E8: Niva Bupa DRHP | F8: Page 15, Industry Report
A9: M5 | B9: Overseas Medical % of Total | C9: 0.011 | D9: % | E9: Niva Bupa DRHP | F9: Page 15, Industry Report
A10: M6 | B10: Urban Digital Addressable % | C10: 0.6 | D10: % | E10: Industry Estimate | F10: Redseer Analysis
A11: M7 | B11: Target Income Segment % | C11: 0.35 | D11: % | E11: CBDT Calculation | F11: Income >5L / Total
A12: M8 | B12: 5Y Capture Rate % | C12: 0.15 | D12: % | E12: Model Assumption | F12: Conservative
A13: M9 | B13: Health Insurance Growth CAGR | C13: 0.195 | D13: % | E13: GI Council YB | F13: 10-Year CAGR
A14: M10 | B14: Retail Health Growth FY24 | C14: 0.191 | D14: % | E14: Niva Bupa DRHP | F14: Page 18
A16: CUSTOMER METRICS
A17: C1 | B17: Avg Annual Premium (Retail) | C17: 15000 | D17: ₹ | E17: IRDAI/Industry | F17: Weighted avg
A18: C2 | B18: Premium Growth Rate (Annual) | C18: 0.08 | D18: % | E18: Medical Inflation | F18: CPI Health
A19: C3 | B19: Retention Rate Year 1 | C19: 0.8 | D19: % | E19: Industry Benchmark | F19: New cohort
A20: C4 | B20: Retention Rate Year 2+ | C20: 0.85 | D20: % | E20: Industry Benchmark | F20: Mature cohort
A21: C5 | B21: Avg Policy Duration | C21: 5 | D21: Years | E21: Retention Based | F21: Calculated
A22: C6 | B22: Year 1 New Customers | C22: 50000 | D22: Number | E22: Model Target | F22: Launch year
A23: C7 | B23: Customer Growth Y1-Y2 | C23: 0.4 | D23: % | E23: Model Target | F23: Aggressive
A24: C8 | B24: Customer Growth Y2-Y3 | C24: 0.35 | D24: % | E24: Model Target | F24: Scaling
A25: C9 | B25: Customer Growth Y3-Y4 | C25: 0.3 | D25: % | E25: Model Target | F25: Maturing
A26: C10 | B26: Customer Growth Y4-Y5 | C26: 0.25 | D26: % | E26: Model Target | F26: Steady
A28: FINANCIAL METRICS
A29: F1 | B29: Claims Ratio Target | C29: 0.65 | D29: % | E29: SAHI Benchmark | F29: Star Health 66.5%
A30: F2 | B30: Expense Ratio Target | C30: 0.25 | D30: % | E30: Digital Efficiency | F30: vs 30% traditional
A31: F3 | B31: Gross Margin | C31: =1-C29-C30 | D31: % | E31: Calculated | F31: 1 - Claims - Expense
A32: F4 | B32: Discount Rate (WACC) | C32: 0.12 | D32: % | E32: Industry WACC | F32: Insurance sector
A33: F5 | B33: CAC D2C Organic | C33: 1500 | D33: ₹ | E33: Industry Est | F33: SEO/Content
A34: F6 | B34: CAC D2C Paid | C34: 3000 | D34: ₹ | E34: Industry Est | F34: Performance mktg
A35: F7 | B35: CAC Aggregators | C35: 4500 | D35: ₹ | E35: PolicyBazaar | F35: Commission based
A36: F8 | B36: CAC Agents/Brokers | C36: 6000 | D36: ₹ | E36: Commission | F36: 15-20% of premium
A37: F9 | B37: CAC Bancassurance | C37: 2500 | D37: ₹ | E37: Bank Partnership | F37: Lower commission
A38: F10 | B38: CAC Reduction Rate YoY | C38: 0.08 | D38: % | E38: Efficiency Gains | F38: Scale benefits
A40: CHANNEL MIX
A41: CH1 | B41: D2C Organic % | C41: 0.15 | D41: % | E41: Target | F41: App organic
A42: CH2 | B42: D2C Paid % | C42: 0.25 | D42: % | E42: Target | F42: Performance
A43: CH3 | B43: Aggregators % | C43: 0.2 | D43: % | E43: Target | F43: PolicyBazaar etc
A44: CH4 | B44: Agents/Brokers % | C44: 0.3 | D44: % | E44: Target | F44: Traditional
...

Sheet B_Waterfall
A1: ICICI LOMBARD D2C HEALTH INSURANCE - OPPORTUNITY WATERFALL
A2: All values linked to Assumptions sheet | TAM → SAM → SOM Analysis
A4: TAM → SAM → SOM WATERFALL | H4: DATA SOURCES
A5: Step | B5: Description | C5: Value (₹ Cr) | D5: Formula | E5: % of TAM | H5: Source | I5: Publisher | J5: Date
A6: 1 | B6: TAM: Total Health Insurance Market | C6: =A_Assumptions!C5 | D6: =A_Assumptions!C5 | E6: 100% | H6: CBDT ITR AY23-24 | I6: Income Tax Dept | J6: Jun 2024
A7: 2 | B7: Filter: Retail Health Only (38.7%) | C7: =C6*A_Assumptions!C6 | D7: =TAM × Retail% | E7: =C7/C6 | H7: IRDAI AR 2023-24 | I7: IRDAI | J7: Dec 2024
A8: 3 | B8: Filter: Urban Digital Addressable (60%) | C8: =C7*A_Assumptions!C10 | D8: =Retail × Urban% | E8: =C8/C6 | H8: GI Council YB 23-24 | I8: GI Council | J8: Feb 2025
A9: 4 | B9: Filter: Target Income >5L (35%) | C9: =C8*A_Assumptions!C11 | D9: =Urban × Income% | E9: =C9/C6 | H9: Niva Bupa DRHP | I9: Niva Bupa | J9: Jun 2024
A10: 5 | B10: SOM: 5-Year Realistic Capture (15%) | C10: =C9*A_Assumptions!C12 | D10: =Target × Capture% | E10: =C10/C6 | H10: Star Health AR | I10: Star Health | J10: FY24
B11: D2C OPPORTUNITY (SOM) | C11: =C10 | D11: 5-Year Target | E11: =E10 | H11: ICICI Lombard AR | I11: ICICI Lombard | J11: FY24
A14: UNIT ECONOMICS (LTV/CAC)
A15: Metric | B15: Value | C15: Formula | D15: Benchmark | E15: Status
A16: Avg Annual Premium | B16: =A_Assumptions!C17 | C16: =Assumptions!C17 | D16: ₹12,000 - ₹20,000 | E16: =IF(B16>=12000,"GOOD","LOW")
A17: Gross Margin % | B17: =1-A_Assumptions!C29-A_Assumptions!C30 | C17: =1-Claims%-Expense% | D17: >8% | E17: =IF(B17>=0.08,"GOOD","IMPROVE")
A18: Avg Policy Life (Years) | B18: =A_Assumptions!C21 | C18: =Assumptions!C21 | D18: >4 years | E18: =IF(B18>=4,"GOOD","LOW")
A19: Customer LTV | B19: =B16*B17*B18 | C19: =Premium×Margin×Years | D19: >₹20,000 | E19: =IF(B19>=20000,"GOOD","IMPROVE")
A20: Blended CAC | B20: =A_Assumptions!C33*A_Assumptions!C41+A_Assumptions!C34*A_Assumptions!C42+A_Assumptions!C35*A_Assumptions!C43+A_Assumptions!C36*A_Assumptions!C44+A_Assumptions!C37*A_Assumptions!C45 | C20: =Σ(CAC×Channel%) | D20: <₹4,000 | E20: =IF(B20<=4000,"GOOD","HIGH")
A21: LTV:CAC Ratio | B21: =B19/B20 | C21: =LTV/CAC | D21: >3:1 | E21: =IF(B21>=3,"HEALTHY","IMPROVE")
A22: Payback Period (Months) | B22: =B20/(B16*B17/12) | C22: =CAC/(MonthlyMargin) | D22: <18 months | E22: =IF(B22<=18,"GOOD","LONG")
A25: 5-YEAR PROJECTION SUMMARY
A26: Metric | B26: Year 1 | C26: Year 2 | D26: Year 3 | E26: Year 4 | F26: Year 5 | G26: 5Y Total
A27: New Customers | B27: =A_Assumptions!C22 | C27: =B27*(1+A_Assumptions!C23) | D27: =C27*(1+A_Assumptions!C24) | E27: =D27*(1+A_Assumptions!C25) | F27: =E27*(1+A_Assumptions!C26) | G27: =SUM(B27:F27)
A28: Retained Customers | B28: 0 | C28: =B29*A_Assumptions!C19 | D28: =C29*A_Assumptions!C20 | E28: =D29*A_Assumptions!C20 | F28: =E29*A_Assumptions!C20 | G28: =F28
A29: Total Customers | B29: =B27+B28 | C29: =C27+C28 | D29: =D27+D28 | E29: =E27+E28 | F29: =F27+F28 | G29: =F29
A30: Avg Premium (₹) | B30: =A_Assumptions!C17 | C30: =B30*(1+A_Assumptions!C18) | D30: =C30*(1+A_Assumptions!C18) | E30: =D30*(1+A_Assumptions!C18) | F30: =E30*(1+A_Assumptions!C18) | G30: =AVERAGE(B30:F30)
A31: GWP (₹ Cr) | B31: =B29*B30/10000000 | C31: =C29*C30/10000000 | D31: =D29*D30/10000000 | E31: =E29*E30/10000000 | F31: =F29*F30/10000000 | G31: =SUM(B31:F31)
A32: Gross Margin (₹ Cr) | B32: =B31*B17 | C32: =C31*B17 | D32: =D31*B17 | E32: =E31*B17 | F32: =F31*B17 | G32: =SUM(B32:F32)
A33: CAC Spend (₹ Cr) | B33: =B27*B20/10000000 | C33: =C27*B20*(1-A_Assumptions!C38)/10000000 | D33: =D27*B20*(1-A_Assumptions!C38)^2/10000000 | E33: =E27*B20*(1-A_Assumptions!C38)^3/10000000 | F33: =F27*B20*(1-A_Assumptions!C38)^4/10000000 | G33: =SUM(B33:F33)
A34: Contribution (₹ Cr) | B34: =B32-B33 | C34: =C32-C33 | D34: =D32-D33 | E34: =E32-E33 | F34: =F32-F33 | G34: =SUM(B34:F34)
A35: CAGR | B35: - | C35: - | D35: - | E35: - | F35: - | G35: =(F31/B31)^(1/4)-1
A38: KEY OUTPUTS
A39: 5-Year SOM Target | B39: =C10 | C39: ₹ Crore
A40: Year 5 Customer Base | B40: =F29 | C40: Customers
A41: Year 5 GWP | B41: =F31 | C41: ₹ Crore
A42: 5-Year Total GWP | B42: =G31 | C42: ₹ Crore
A43: 5-Year Contribution | B43: =G34 | C43: ₹ Crore
A44: LTV:CAC Ratio | B44: =B21 | C44: :1
A45: GWP CAGR | B45: =G35 | C45: %

Sheet C_CBDT_Data
A1: CBDT ITR STATISTICS AY 2023-24
A2: Source: https://incometaxindia.gov.in | Page 9, Table 1.1
A4: Slab | B4: Income Range | C4: Filers | D4: % Total | E4: Cumulative | F4: Target | G4: Avg Premium | H4: TAM (₹Cr)
A5: 1 | B5: Income = 0 | C5: 1441175 | D5: =C5/C23 | E5: =D5 | F5: No | G5: 0 | H5: 0
A6: 2 | B6: >0 to ≤1.5L | C6: 4144666 | D6: =C6/C23 | E6: =E5+D6 | F6: No | G6: 0 | H6: 0
A7: 3 | B7: >1.5L to ≤2L | C7: 1509747 | D7: =C7/C23 | E7: =E6+D7 | F7: No | G7: 0 | H7: 0
A8: 4 | B8: >2L to ≤2.5L | C8: 3036825 | D8: =C8/C23 | E8: =E7+D8 | F8: No | G8: 0 | H8: 0
A9: 5 | B9: >2.5L to ≤3.5L | C9: 5946214 | D9: =C9/C23 | E9: =E8+D9 | F9: No | G9: 5000 | H9: 0
A10: 6 | B10: >3.5L to ≤4L | C10: 4055198 | D10: =C10/C23 | E10: =E9+D10 | F10: No | G10: 5000 | H10: 0
A11: 7 | B11: >4L to ≤4.5L | C11: 6024031 | D11: =C11/C23 | E11: =E10+D11 | F11: Low | G11: 6000 | H11: 0
A12: 8 | B12: >4.5L to ≤5L | C12: 12600689 | D12: =C12/C23 | E12: =E11+D12 | F12: Low | G12: 8000 | H12: 0
A13: 9 | B13: >5L to ≤5.5L | C13: 6154414 | D13: =C13/C23 | E13: =E12+D13 | F13: YES | G13: 10000 | H13: =C13*G13/10000000
A14: 10 | B14: >5.5L to ≤9.5L | C14: 20697590 | D14: =C14/C23 | E14: =E13+D14 | F14: YES | G14: 12000 | H14: =C14*G14/10000000
A15: 11 | B15: >9.5L to ≤10L | C15: 1084818 | D15: =C15/C23 | E15: =E14+D15 | F15: YES | G15: 15000 | H15: =C15*G15/10000000
A16: 12 | B16: >10L to ≤15L | C16: 6379208 | D16: =C16/C23 | E16: =E15+D16 | F16: YES | G16: 18000 | H16: =C16*G16/10000000
A17: 13 | B17: >15L to ≤20L | C17: 2503932 | D17: =C17/C23 | E17: =E16+D17 | F17: YES | G17: 22000 | H17: =C17*G17/10000000
A18: 14 | B18: >20L to ≤25L | C18: 1240128 | D18: =C18/C23 | E18: =E17+D18 | F18: YES | G18: 28000 | H18: =C18*G18/10000000
A19: 15 | B19: >25L to ≤50L | C19: 1953619 | D19: =C19/C23 | E19: =E18+D19 | F19: YES | G19: 35000 | H19: =C19*G19/10000000
A20: 16 | B20: >50L to ≤1Cr | C20: 589762 | D20: =C20/C23 | E20: =E19+D20 | F20: PREMIUM | G20: 50000 | H20: =C20*G20/10000000
A21: 17 | B21: >1Cr to ≤5Cr | C21: 291929 | D21: =C21/C23 | E21: =E20+D21 | F21: PREMIUM | G21: 75000 | H21: =C21*G21/10000000
A22: 18 | B22: >5Cr+ | C22: 74065 | D22: =C22/C23 | E22: =E21+D22 | F22: PREMIUM | G22: 100000 | H22: =C22*G22/10000000
A23: TOTAL | B23: All Filers | C23: =SUM(C5:C22) | D23: 100% | E23: 100% | H23: =SUM(H5:H22)
A25: TARGET SEGMENT (>5L) | B25: =SUM(C13:C22) | C25: =B25/C23

Sheet D_Competitors
A1: COMPETITOR ANALYSIS - ANNUAL REPORTS & DRHP DATA
A3: Rank | B3: Insurer | C3: Type | D3: GWP (₹Cr) | E3: Share | F3: Health GWP | G3: Claims% | H3: Combined% | I3: Growth | J3: Solvency | K3: Source | L3: Page
A4: 1 | B4: New India Assurance | C4: PSU | D4: 40364 | E4: 13.1% | F4: 12109 | G4: 97.2% | H4: 116% | I4: 8.9% | J4: 1.67x | K4: IRDAI AR | L4: Ch5
A5: 2 | B5: ICICI Lombard | C5: Private | D5: 24776 | E5: 8.7% | F5: 2800 | G5: 76.5% | H5: 103.8% | I5: 20.4% | J5: 2.69x | K5: Company AR | L5: Fin
A6: 3 | B6: Bajaj Allianz | C6: Private | D6: 22000 | E6: 7.7% | F6: 3300 | G6: 78% | H6: 99.9% | I6: 14.8% | J6: 3.49x | K6: ICRA | L6: Rating
A7: 4 | B7: Star Health | C7: SAHI | D7: 15254 | E7: 5.3% | F7: 15254 | G7: 66.5% | H7: 97.3% | I7: 22.3% | J7: 2.15x | K7: Company AR | L7: Fin
A8: 5 | B8: United India | C8: PSU | D8: 19852 | E8: 6.8% | F8: 5956 | G8: 97% | H8: 118% | I8: 5% | J8: 1.52x | K8: IRDAI AR | L8: Ch5
A9: 6 | B9: HDFC ERGO | C9: Private | D9: 9000 | E9: 3.1% | F9: 1800 | G9: 82% | H9: 102% | I9: 12% | J9: 2.35x | K9: Company AR | L9: Fin
A10: 7 | B10: Tata AIG | C10: Private | D10: 8500 | E10: 2.9% | F10: 1700 | G10: 80% | H10: 100% | I10: 18% | J10: 2.45x | K10: Company AR | L10: Fin
A11: 8 | B11: Niva Bupa | C11: SAHI | D11: 5499 | E11: 1.9% | F11: 5499 | G11: 70% | H11: 95% | I11: 41% | J11: 1.85x | K11: DRHP | L11: Pg12
A12: 9 | B12: Care Health | C12: SAHI | D12: 4500 | E12: 1.6% | F12: 4500 | G12: 68% | H12: 93% | I12: 20% | J12: 1.92x | K12: Company AR | L12: Fin
A13: 10 | B13: Aditya Birla | C13: SAHI | D13: 3290 | E13: 1.1% | F13: 3290 | G13: 72% | H13: 96% | I13: 48% | J13: 1.75x | K13: Company AR | L13: Fin
A16: ICICI LOMBARD GAP ANALYSIS
A17: Metric | B17: ICICI | C17: Star Health | D17: Gap | E17: Target | F17: Action
A18: Retail Health Share | B18: 2.9% | C18: 33% | D18: =C18-B18 | E18: 10% | F18: D2C Focus
A19: Claims Ratio | B19: 76.5% | C19: 66.5% | D19: =B19-C19 | E19: 65% | F19: Underwriting
A20: Digital Share | B20: 17.4% | C20: 15% | D20: =B20-C20 | E20: 35% | F20: App Launch
A21: Agent Network | B21: 150K | C21: 701K | D21: =C21-B21 | E21: 250K | F21: Hybrid Model
A22: Renewal Rate | B22: 80% | C22: 82% | D22: =C22-B22 | E22: 90% | F22: Engagement

Sheet E_LTV_Detail
A1: CUSTOMER LIFETIME VALUE - DETAILED NPV CALCULATION
A3: All inputs linked to Assumptions sheet
A5: Year | B5: Premium | C5: Retention | D5: Expected Premium | E5: Gross Margin | F5: Discount | G5: PV Margin | H5: Cumulative
A6: 1 | B6: =A_Assumptions!C17 | C6: 100% | D6: =B6*C6 | E6: =D6*(1-A_Assumptions!C29-A_Assumptions!C30) | F6: =1/(1+A_Assumptions!C32)^A6 | G6: =E6*F6 | H6: =G6
A7: 2 | B7: =B6*(1+A_Assumptions!C18) | C7: =A_Assumptions!C19 | D7: =B7*C7 | E7: =D7*(1-A_Assumptions!C29-A_Assumptions!C30) | F7: =1/(1+A_Assumptions!C32)^A7 | G7: =E7*F7 | H7: =H6+G7
A8: 3 | B8: =B7*(1+A_Assumptions!C18) | C8: =C7*A_Assumptions!C20 | D8: =B8*C8 | E8: =D8*(1-A_Assumptions!C29-A_Assumptions!C30) | F8: =1/(1+A_Assumptions!C32)^A8 | G8: =E8*F8 | H8: =H7+G8
A9: 4 | B9: =B8*(1+A_Assumptions!C18) | C9: =C8*A_Assumptions!C20 | D9: =B9*C9 | E9: =D9*(1-A_Assumptions!C29-A_Assumptions!C30) | F9: =1/(1+A_Assumptions!C32)^A9 | G9: =E9*F9 | H9: =H8+G9
A10: 5 | B10: =B9*(1+A_Assumptions!C18) | C10: =C9*A_Assumptions!C20 | D10: =B10*C10 | E10: =D10*(1-A_Assumptions!C29-A_Assumptions!C30) | F10: =1/(1+A_Assumptions!C32)^A10 | G10: =E10*F10 | H10: =H9+G10
A12: 5-YEAR LTV | B12: =H10
A15: CAC BY CHANNEL
A16: Channel | B16: CAC (₹) | C16: Mix % | D16: Weighted CAC
A17: D2C Organic | B17: =A_Assumptions!C33 | C17: =A_Assumptions!C41 | D17: =B17*C17
A18: D2C Paid | B18: =A_Assumptions!C34 | C18: =A_Assumptions!C42 | D18: =B18*C18
A19: Aggregators | B19: =A_Assumptions!C35 | C19: =A_Assumptions!C43 | D19: =B19*C19
A20: Agents/Brokers | B20: =A_Assumptions!C36 | C20: =A_Assumptions!C44 | D20: =B20*C20
A21: Bancassurance | B21: =A_Assumptions!C37 | C21: =A_Assumptions!C45 | D21: =B21*C21
A22: BLENDED CAC | B22: =SUM(D17:D21) | C22: =SUM(C17:C21) | D22: =SUM(D17:D21)
A25: LTV:CAC RATIO | B25: =B12/B22
A26: Payback (Months) | B26: =B22/(A_Assumptions!C17*(1-A_Assumptions!C29-A_Assumptions!C30)/12)

Sheet F_Sources
A1: DATA SOURCES WITH FULL CITATIONS
A3: ID | B3: Document | C3: Publisher | D3: URL | E3: Date | F3: Pages Used | G3: Key Data
A4: S01 | B4: ITR Statistics AY 2023-24 | C4: CBDT, Ministry of Finance | D4: https://incometaxindia.gov.in/Documents/Direct%20Tax%20Data/Approved-version-Income-Tax-Return-Statistics-for-the-AY-2023-24.pdf | E4: Jun 2024 | F4: 6, 9, 10 | G4: 7.97Cr filers, income slabs
A5: S02 | B5: IRDAI Annual Report 2023-24 | C5: IRDAI | D5: https://irdai.gov.in/document-detail?documentId=6436847 | E5: Dec 2024 | F5: All | G5: ₹11.19T premium, penetration
A6: S03 | B6: GI Council Yearbook 2023-24 | C6: General Insurance Council | D6: https://www.gicouncil.in/yearbook/2023-24/ | E6: Feb 2025 | F6: Exec Summary | G6: ₹2.90T GDPI, 40.3% health
A7: S04 | B7: Niva Bupa DRHP Industry Report | C7: Niva Bupa (Redseer) | D7: https://transactions.nivabupa.com/pages/doc/drhp/Industry-Report.pdf | E7: Jun 2024 | F7: 1-50 | G7: Retail 38.7%, SAHI 27.1%
A8: S05 | B8: Niva Bupa Annual Report FY24 | C8: Niva Bupa Health Insurance | D8: https://transactions.nivabupa.com/pages/doc/pub-dis/annual-reports/Annual-Report-FY-2023-24.pdf | E8: FY24 | F8: Financial | G8: ₹5,499Cr GWP, 41% growth
A9: S06 | B9: Star Health Annual Report FY24 | C9: Star Health & Allied | D9: https://www.starhealth.in/investors/annual-report/ | E9: FY24 | F9: Financial | G9: ₹15,254Cr, 66.5% claims
A10: S07 | B10: ICICI Lombard Annual Report FY24 | C10: ICICI Lombard GIC | D10: https://www.icicilombard.com/docs/default-source/financial-information/annualreport2024.pdf | E10: FY24 | F10: Full | G10: ₹24,776Cr, 2.9% retail
A11: S08 | B11: Go Digit DRHP | C11: Go Digit General Insurance | D11: https://www.godigit.com/investor-relations | E11: 2024 | F11: Industry | G11: Digital insurance metrics
A12: S09 | B12: Care Health Annual Report | C12: Care Health Insurance | D12: https://www.careinsurance.com/investor-relations | E12: FY24 | F12: Financial | G12: ₹4,500Cr, 100% CSR
A13: S10 | B13: Aditya Birla Health Report | C13: ABHI | D13: https://www.adityabirlacapital.com/healthinsurance/ | E13: FY24 | F13: Financial | G13: ₹3,290Cr, 48% CAGR
A14: S11 | B14: HDFC ERGO Annual Report | C14: HDFC ERGO GIC | D14: https://www.hdfcergo.com/about-us/financial/annual-reports | E14: FY24 | F14: Financial | G14: ₹9,000Cr estimated
... A17: S14 | B17: Census India Projections | C17: Registrar General | D17: https://censusindia.gov.in/ | E17: 2011+Proj | F17: Demographics | G17: 1.44B population
